Workbook

Sheet Sheet1
A1: 运营 | B1: 门店号 | C1: 战区 | D1: 省份 | E1: 店铺名称 | F1: 预计开业 | G1: 实际开业 | H1: 建店单 | I1: 资料包 | J1: 当前审批状态 | K1: 审批流程
A2: 王 | B2: 2327 | C2: 浙江 | D2: 浙江 | E2: 诸暨大润发店 | F2: 46016 | G2: 46016 | H2: 已提交 | I2: 已收集
A3: 段 | B3: 2401 | C3: 安徽 | D3: 江苏 | E3: 徐州怡和广场店 | F3: 46016 | G3: 46016 | H3: 已提交 | I3: 已收集
A4: 陈 | B4: 2346 | C4: 华中 | D4: 湖北 | E4: 咸宁通城店 | F4: 46016 | G4: 46016 | H4: 已提交 | I4: 已收集
A5: 陈 | B5: 2334 | C5: 华中 | D5: 湖北 | E5: 咸宁温泉店 | F5: 46016 | G5: 46016 | H5: 已提交 | I5: 已收集
A6: 钟 | B6: 2365 | C6: 粤闽 | D6: 广东 | E6: 梅州丰良店 | F6: 46016 | G6: 46016 | H6: 已提交 | I6: 已收集
A7: 吴 | B7: 2398 | C7: 华中 | D7: 新疆 | E7: 博尔塔拉精河店 | F7: 46016 | G7: 46016 | H7: 已提交 | I7: 已收集
A8: 王 | B8: 2385 | C8: 西南 | D8: 云南 | E8: 昆明云岭天骄店 | F8: 46016 | G8: 46016 | H8: 已提交 | I8: 已收集 | J8: 已通过 | K8: =VLOOKUP(B8,[1]线上建店审批明细!$A:$E,5,0) -> 已抄送 | 线上督导-鹿世鸣-督导部 已抄送 01/11 16:13; 已同意 | 贺龙娇 已同意 01/12 16:40; 已同意 | 杨文慧 已同意 01/12 17:15; 已同意 | 施工监理-范钟欣-13817733545 已同意 01/12 17:39; 已同意 | 王伟清 已同意 01/13 10:01; 已同意 | 刘崇宇-18616022203-督导部 已同意 01/13 17:42; 已同意 | 蔡文佳-18916500662-线下运营部 已同意 01/13 21:12; 已同意 | 线下堂食助理-婷婷 已同意 01/14 10:24; 已同意 | 单玮-13816935059-督导部 已同意 01/14 18:33; 已抄送 | 卢家豪 已抄送 01/14 18:33; 已抄送 | 抖音&快手-周幂-17521714387 已抄送 01/14 18:33; 已同意 | 苏磊 已同意 01/14 18:33; 已抄送 | 翁嘉隆-线上运营总监-13611699917 已抄送 01/14 18:33; 已同意 | 陈宇航-线上助理-18350349892 三平台建店完成 已同意 01/19 17:08; 已抄送 | 谢芳 已抄送 01/19 17:08; 已抄送 | 黄琪艳 已抄送 01/19 17:08; 已抄送 | 王京海 已抄送 01/19 17:08
A9: 钟 | B9: 2296 | C9: 粤桂 | D9: 广东 | E9: 珠海金鼎店 | F9: 46017 | G9: 46017 | H9: 已提交 | I9: 已收集
A10: 钟 | B10: 2203 | C10: 粤桂 | D10: 广东 | E10: 肇庆幸福湖畔店 | F10: 46017 | G10: 46017 | H10: 已提交 | I10: 已收集
A11: 陈 | B11: 2410 | C11: 西南 | D11: 湖南 | E11: 娄底涟钢店 | F11: 46017 | G11: 46017 | H11: 已提交 | I11: 已收集
A12: 陈 | B12: 2237 | C12: 华中 | D12: 湖北 | E12: 潜江江汉路店 | F12: 46017 | G12: 46017 | H12: 已提交 | I12: 已收集
A13: 窦 | B13: 2404 | C13: 华中 | D13: 河南 | E13: 永城永兴街店 | F13: 46017 | G13: 46017 | H13: 已提交 | I13: 已收集
A14: 钟 | B14: 2338 | C14: 粤桂 | D14: 海南 | E14: 琼海元亨街店 | F14: 46017 | G14: 46017 | H14: 已提交 | I14: 已收集
A15: 吴 | B15: 2311 | C15: 华中 | D15: 江西 | E15: 兴国翡翠广场店 | F15: 46018 | G15: 46018 | H15: 已提交 | I15: 已收集
A16: 马 | B16: 2352 | C16: 华北 | D16: 河北 | E16: 邯郸复兴商贸城店 | F16: 46018 | G16: 46018 | H16: 已提交 | I16: 已收集
A17: 钟 | B17: 2354 | C17: 粤桂 | D17: 广西 | E17: 柳州中天城店 | F17: 46018 | G17: 46018 | H17: 已提交 | I17: 已收集
A18: 钟 | B18: 2362 | C18: 粤桂 | D18: 广东 | E18: 中山沙溪店 | F18: 46018 | G18: 46018 | H18: 已提交 | I18: 已收集
A19: 钟 | B19: 2414 | C19: 粤桂 | D19: 广东 | E19: 长安横增店 | F19: 46018 | G19: 46018 | H19: 已提交 | I19: 已收集 | J19: 已通过 | K19: =VLOOKUP(B19,[1]线上建店审批明细!$A:$E,5,0) -> 已抄送 | 线上督导服务号-如有异议请联系区域经理（此账号不做回复） 已抄送 01/13 10:13; 已抄送 | 线上督导-鹿世鸣-督导部 已抄送 01/13 10:13; 已同意 | 贺龙娇 已同意 01/14 15:36; 已同意 | 杨文慧 已同意 01/14 15:52; 已同意 | 施工监理-范钟欣-13817733545 已同意 01/14 17:33; 已同意 | 王伟清 已同意 01/14 17:50; 已同意 | 刘崇宇-18616022203-督导部 已同意 01/15 13:44; 已同意 | 蔡文佳-18916500662-线下运营部 已同意 01/15 15:00; 已同意 | 线下堂食助理-婷婷 已同意 01/15 15:39; 已同意 | 单玮-13816935059-督导部 已同意 01/15 17:15; 已抄送 | 卢家豪 已抄送 01/15 17:15; 已抄送 | 抖音&快手-周幂-17521714387 已抄送 01/15 17:15; 已同意 | 苏磊 已同意 01/15 17:15; 已抄送 | 翁嘉隆-线上运营总监-13611699917 已抄送 01/15 17:15; 已同意 | 陈宇航-线上助理-18350349892 三平台建店完成 已同意 01/19 17:11; 已抄送 | 谢芳 已抄送 01/19 17:11; 已抄送 | 黄琪艳 已抄送 01/19 17:11; 已抄送 | 王京海 已抄送 01/19 17:11
A20: 钟 | B20: 2426 | C20: 粤桂 | D20: 广东 | E20: 广州新塘广场店 | F20: 46018 | G20: 46018 | H20: 已提交 | I20: 已收集
A21: 段 | B21: 2411 | C21: 江苏 | D21: 江苏 | E21: 苏州盛泽欧盛花园店 | F21: 46019 | G21: 46019 | H21: 已提交 | I21: 已收集
A22: 窦 | B22: 2453 | C22: 华中 | D22: 河南 | E22: 驻马店黄海学院店 | F22: 46020 | G22: 46020 | H22: 已提交 | I22: 已收集
A23: 段 | B23: 2257 | C23: 安徽 | D23: 江苏 | E23: 南京奥体店 | F23: 46020 | G23: 46020 | H23: 已提交 | I23: 已收集
A24: 吴 | B24: 2442 | C24: 西南 | D24: 重庆 | E24: 重庆邮电大学店 | F24: 46020 | G24: 46020 | H24: 已提交 | I24: 已收集
A25: 钟 | B25: 2369 | C25: 粤桂 | D25: 广东 | E25: 佛山乐从天佑城店 | F25: 46386 | G25: 46386 | H25: 已提交 | I25: 已收集
A26: 马 | B26: 2421 | C26: 华北 | D26: 河北 | E26: 承德宽城店 | F26: 46022 | G26: 46022 | H26: 已提交 | I26: 已收集
A27: 王 | B27: 2470 | C27: 浙江 | D27: 浙江 | E27: 温州仙岩店 | F27: 46022 | G27: 46022 | H27: 已提交 | I27: 已收集
A28: 陈 | B28: 2376 | C28: 华中 | D28: 湖北 | E28: 武汉东立国际店 | F28: 46023 | G28: 46023 | H28: 已提交 | I28: 已收集 | J28: 已通过 | K28: =VLOOKUP(B28,[1]线上建店审批明细!$A:$E,5,0) -> 已抄送 | 线上督导服务号-如有异议请联系区域经理（此账号不做回复） 已抄送 01/25 10:44; 已抄送 | 谢芳 已抄送 01/25 10:44; 已抄送 | 线上督导-鹿世鸣-督导部 已抄送 01/25 10:44; 已同意 | 李婕 已同意 01/26 19:06; 已同意 | 杨文慧 已同意 01/26 19:16; 已同意 | 施工监理-范钟欣-13817733545 已同意 01/27 09:12; 已同意 | 王伟清 已同意 01/27 09:13; 已同意 | 刘崇宇-18616022203-督导部 已同意 01/30 13:46; 已同意 | 蔡文佳-18916500662-线下运营部 已同意 01/30 16:08; 已同意 | 线下堂食助理-婷婷 已同意 01/30 16:14; 已同意 | 单玮-13816935059-督导部 已同意 01/30 16:55; 已抄送 | 卢家豪 已抄送 01/30 16:55; 已抄送 | 抖音&快手-周幂-17521714387 已抄送 01/30 16:55; 已同意 | 苏磊 已同意 01/30 17:04; 已抄送 | 翁嘉隆-线上运营总监-13611699917 已抄送 01/30 17:04; 已同意 | 陈宇航-线上助理-18350349892 门店换证 已同意 02/05 11:46; 已抄送 | 谢芳 已抄送 02/05 11:46; 已抄送 | 黄琪艳 已抄送 02/05 11:46; 已抄送 | 王京海 已抄送 02/05 11:46
A29: 吴 | B29: 2420 | C29: 华中 | D29: 陕西 | E29: 西安学府大街店 | F29: 45658 | G29: 45658 | H29: 已提交 | I29: 已收集 | J29: 已通过 | K29: =VLOOKUP(B29,[1]线上建店审批明细!$A:$E,5,0) -> 已抄送 | 线上督导服务号-如有异议请联系区域经理（此账号不做回复） 已抄送 01/13 15:25; 已抄送 | 谢芳 已抄送 01/13 15:25; 已抄送 | 线上督导-鹿世鸣-督导部 已抄送 01/13 15:25; 已同意 | 贺龙娇 已同意 01/13 20:58; 已同意 | 谢珍珍 已同意 01/14 10:20; 已同意 | 施工监理-范钟欣-13817733545 已同意 01/14 17:11; 已同意 | 王伟清 已同意 01/14 17:51; 已同意 | 刘崇宇-18616022203-督导部 已同意 01/15 13:43; 已同意 | 蔡文佳-18916500662-线下运营部 已同意 01/15 15:03; 已同意 | 线下堂食助理-婷婷 已同意 01/15 15:38; 已同意 | 单玮-13816935059-督导部 已同意 01/15 17:15; 已抄送 | 卢家豪 已抄送 01/15 17:15; 已抄送 | 抖音&快手-周幂-17521714387 已抄送 01/15 17:15; 已同意 | 苏磊 已同意 01/15 17:15; 已抄送 | 翁嘉隆-线上运营总监-13611699917 已抄送 01/15 17:15; 已同意 | 陈宇航-线上助理-18350349892 三平台建店完成 已同意 01/19 17:12; 已抄送 | 谢芳 已抄送 01/19 17:12; 已抄送 | 黄琪艳 已抄送 01/19 17:12; 已抄送 | 王京海 已抄送 01/19 17:12
A30: 吴 | B30: 2382 | C30: 华中 | D30: 陕西 | E30: 西安鄠邑店 | F30: 46023 | G30: 46023 | H30: 已提交 | I30: 已收集
A31: 吴 | B31: 2481 | C31: 华中 | D31: 江西 | E31: 瑞金文化广场店 | F31: 46024 | G31: 46024 | H31: 已提交 | I31: 已收集 | J31: 已通过 | K31: =VLOOKUP(B31,[1]线上建店审批明细!$A:$E,5,0) -> 已抄送 | 线上督导服务号-如有异议请联系区域经理（此账号不做回复） 已抄送 01/12 11:31; 已抄送 | 线上督导-鹿世鸣-督导部 已抄送 01/12 11:31; 已同意 | 诸静逸 已同意 01/12 11:41; 已同意 | 谢珍珍 已同意 01/12 11:44; 已同意 | 施工监理-范钟欣-13817733545 已同意 01/12 15:52; 已同意 | 王伟清 已同意 01/12 16:08; 已同意 | 刘崇宇-18616022203-督导部 已同意 01/12 17:44; 已同意 | 蔡文佳-18916500662-线下运营部 已同意 01/13 11:26; 已同意 | 线下堂食助理-婷婷 已同意 01/13 11:41; 已同意 | 单玮-13816935059-督导部 已同意 01/13 16:55; 已抄送 | 卢家豪 已抄送 01/13 16:55; 已抄送 | 抖音&快手-周幂-17521714387 已抄送 01/13 16:55; 已同意 | 苏磊 已同意 01/13 16:55; 已抄送 | 翁嘉隆-线上运营总监-13611699917 已抄送 01/13 16:55; 已同意 | 陈宇航-线上助理-18350349892 三平台建店完成 已同意 01/17 17:15; 已抄送 | 谢芳 已抄送 01/17 17:15; 已抄送 | 黄琪艳 已抄送 01/17 17:15; 已抄送 | 王京海 已抄送 01/17 17:15
A32: 钟 | B32: 2446 | C32: 粤桂 | D32: 广东 | E32: 东莞横沥时代倾城店 | F32: 46024 | G32: 46024 | H32: 已提交 | I32: 已收集 | J32: 已通过 | K32: =VLOOKUP(B32,[1]线上建店审批明细!$A:$E,5,0) -> 已抄送 | 线下堂食助理-婷婷 已抄送 01/09 14:35; 已抄送 | 蔡文佳-18916500662-线下运营部 已抄送 01/09 14:35; 已抄送 | 谢芳 已抄送 01/09 14:35; 已抄送 | 线上督导-鹿世鸣-督导部 已抄送 01/09 14:35; 已转审 | 贺龙娇 已转审 01/10 17:26; 已同意 | 诸静逸 已同意 01/12 12:28; 已同意 | 杨文慧 已同意 01/12 12:30; 已同意 | 施工监理-范钟欣-13817733545 已同意 01/12 15:51; 已同意 | 王伟清 已同意 01/12 16:09; 已同意 | 刘崇宇-18616022203-督导部 已同意 01/12 17:43; 已同意 | 蔡文佳-18916500662-线下运营部 已同意 01/13 11:28; 已同意 | 线下堂食助理-婷婷 已同意 01/13 11:41; 已同意 | 单玮-13816935059-督导部 已同意 01/13 16:55; 已抄送 | 卢家豪 已抄送 01/13 16:55; 已抄送 | 抖音&快手-周幂-17521714387 已抄送 01/13 16:55; 已同意 | 苏磊 已同意 01/13 16:56; 已抄送 | 翁嘉隆-线上运营总监-13611699917 已抄送 01/13 16:56; 已同意 | 陈宇航-线上助理-18350349892 三平台建店完成 已同意 01/17 17:16; 已抄送 | 谢芳 已抄送 01/17 17:16; 已抄送 | 黄琪艳 已抄送 01/17 17:16; 已抄送 | 王京海 已抄送 01/17 17:16
A33: 钟 | B33: 2435 | C33: 粤桂 | D33: 广东 | E33: 东莞三中市场店 | F33: 46025 | G33: 46025 | H33: 已提交 | I33: 已收集 | J33: 审批中 | K33: =VLOOKUP(B33,[1]线上建店审批明细!$A:$E,5,0) -> 已抄送 | 线上督导服务号-如有异议请联系区域经理（此账号不做回复） 已抄送 01/13 15:26; 已抄送 | 谢芳 已抄送 01/13 15:26; 已抄送 | 线上督导-鹿世鸣-督导部 已抄送 01/13 15:26; 已同意 | 贺龙娇 已同意 01/13 20:56; 已同意 | 谢珍珍 已同意 01/14 10:20; 已同意 | 施工监理-范钟欣-13817733545 已同意 01/27 10:34; 已同意 | 王伟清 已同意 01/27 11:09; 已同意 | 刘崇宇-18616022203-督导部 已同意 01/30 13:48; 已同意 | 蔡文佳-18916500662-线下运营部 已同意 01/30 16:15; 已同意 | 线下堂食助理-婷婷 已同意 01/30 16:16; 已同意 | 单玮-13816935059-督导部 已同意 01/30 16:51; 已抄送 | 卢家豪 已抄送 01/30 16:51; 已抄送 | 抖音&快手-周幂-17521714387 已抄送 01/30 16:51; 已同意 | 苏磊 已同意 01/30 17:04; 已抄送 | 翁嘉隆-线上运营总监-13611699917 已抄送 01/30 17:04
A34: 陈 | B34: 2405 | C34: 西南 | D34: 湖南 | E34: 株洲职教城店 | F34: 46025 | G34: 46025 | H34: 已提交 | I34: 已收集
A35: 钟 | B35: 2360 | C35: 粤桂 | D35: 广东 | E35: 惠州三栋店 | F35: 46027 | G35: 46027 | H35: 已提交 | I35: 已收集 | J35: 已通过 | K35: =VLOOKUP(B35,[1]线上建店审批明细!$A:$E,5,0) -> 已抄送 | 线上督导服务号-如有异议请联系区域经理（此账号不做回复） 已抄送 01/12 15:19; 已抄送 | 线上督导-鹿世鸣-督导部 已抄送 01/12 15:19; 已同意 | 贺龙娇 已同意 01/12 16:05; 已同意 | 杨文慧 已同意 01/12 16:14; 已同意 | 施工监理-范钟欣-13817733545 已同意 01/12 16:34; 已同意 | 王伟清 已同意 01/12 18:25; 已同意 | 刘崇宇-18616022203-督导部 已同意 01/27 15:11; 已同意 | 蔡文佳-18916500662-线下运营部 已同意 01/27 20:39; 已同意 | 休息中-线下堂食助理-婷婷 已同意 01/28 09:57; 已同意 | 单玮-13816935059-督导部 已同意 01/28 10:19; 已抄送 | 卢家豪 已抄送 01/28 10:19; 已抄送 | 抖音&快手-周幂-17521714387 已抄送 01/28 10:19; 已同意 | 苏磊 已同意 01/28 10:19; 已抄送 | 翁嘉隆-线上运营总监-13611699917 已抄送 01/28 10:19; 已同意 | 陈宇航-线上助理-18350349892 三平台建店完成 已同意 01/31 11:20; 已抄送 | 谢芳 已抄送 01/31 11:20; 已抄送 | 黄琪艳 已抄送 01/31 11:20; 已抄送 | 王京海 已抄送 01/31 11:20
A36: 王 | B36: 2436 | C36: 华中 | D36: 河南 | E36: 鹤壁体育公园店 | F36: 46026 | G36: 46026 | H36: 已提交 | I36: 已收集 | J36: 已通过 | K36: =VLOOKUP(B36,[1]线上建店审批明细!$A:$E,5,0) -> 已抄送 | 线下堂食助理-婷婷 已抄送 01/08 10:16; 已抄送 | 蔡文佳-18916500662-线下运营部 已抄送 01/08 10:16; 已抄送 | 谢芳 已抄送 01/08 10:16; 已同意 | 贺龙娇 已同意 01/08 15:30; 已同意 | 杨文慧 已同意 01/08 15:43; 已同意 | 施工监理-范钟欣-13817733545 已同意 01/08 15:57; 已同意 | 王伟清 已同意 01/08 15:57; 已同意 | 刘崇宇-18616022203-督导部 已同意 01/08 18:27; 已同意 | 蔡文佳-18916500662-线下运营部 已同意 01/09 16:47; 已同意 | 线下堂食助理-婷婷 已同意 01/09 16:49; 已同意 | 单玮-13816935059-督导部 已同意 01/09 18:37; 已抄送 | 卢家豪 已抄送 01/09 18:37; 已抄送 | 抖音&快手-周幂-17521714387 已抄送 01/09 18:37; 已同意 | 苏磊 已同意 01/09 18:41; 已同意 | 陈宇航-线上助理-18350349892 三平台建店完成 已同意 01/14 14:51; 已抄送 | 谢芳 已抄送 01/14 14:51; 已抄送 | 黄琪艳 已抄送 01/14 14:51; 已抄送 | 王京海 已抄送 01/14 14:51
A37: 窦 | B37: 2463 | C37: 华中 | D37: 河南 | E37: 洛阳南昌路王府井店 | F37: 46026 | G37: 46026 | H37: 已提交 | I37: 已收集 | J37: 已通过 | K37: =VLOOKUP(B37,[1]线上建店审批明细!$A:$E,5,0) -> 已抄送 | 线上督导-鹿世鸣-督导部 已抄送 01/10 17:58; 已同意 | 诸静逸 已同意 01/12 13:32; 已同意 | 杨文慧 已同意 01/12 13:50; 已同意 | 施工监理-范钟欣-13817733545 已同意 01/12 15:48; 已同意 | 王伟清 已同意 01/12 16:09; 已同意 | 刘崇宇-18616022203-督导部 已同意 01/13 17:37; 已同意 | 蔡文佳-18916500662-线下运营部 已同意 01/13 21:10; 已同意 | 线下堂食助理-婷婷 已同意 01/14 10:23; 已同意 | 单玮-13816935059-督导部 已同意 01/14 14:07; 已抄送 | 卢家豪 已抄送 01/14 14:07; 已抄送 | 抖音&快手-周幂-17521714387 已抄送 01/14 14:07; 已同意 | 苏磊 已同意 01/14 14:12; 已抄送 | 翁嘉隆-线上运营总监-13611699917 已抄送 01/14 14:12; 已同意 | 陈宇航-线上助理-18350349892 三平台建店完成 已同意 01/19 17:08; 已抄送 | 谢芳 已抄送 01/19 17:08; 已抄送 | 黄琪艳 已抄送 01/19 17:08; 已抄送 | 王京海 已抄送 01/19 17:08
A38: 钟 | B38: 2328 | C38: 粤桂 | D38: 广东 | E38: 中山海雅缤纷城店 | F38: 46027 | G38: 46027 | H38: 已提交 | I38: 已收集 | J38: 已通过 | K38: =VLOOKUP(B38,[1]线上建店审批明细!$A:$E,5,0) -> 已抄送 | 线上督导-鹿世鸣-督导部 已抄送 01/10 17:15; 已同意 | 贺龙娇 已同意 01/10 17:33; 已同意 | 杨文慧 已同意 01/10 17:45; 已同意 | 施工监理-范钟欣-13817733545 已同意 01/10 17:50; 已同意 | 王伟清 已同意 01/12 10:18; 已同意 | 刘崇宇-18616022203-督导部 已同意 01/12 17:42; 已同意 | 蔡文佳-18916500662-线下运营部 已同意 01/13 11:31; 已同意 | 线下堂食助理-婷婷 已同意 01/13 11:42; 已同意 | 单玮-13816935059-督导部 已同意 01/13 16:55; 已抄送 | 卢家豪 已抄送 01/13 16:55; 已抄送 | 抖音&快手-周幂-17521714387 已抄送 01/13 16:55; 已同意 | 苏磊 已同意 01/13 16:56; 已抄送 | 翁嘉隆-线上运营总监-13611699917 已抄送 01/13 16:56; 已同意 | 陈宇航-线上助理-18350349892 三平台建店完成 已同意 01/17 17:16; 已抄送 | 谢芳 已抄送 01/17 17:16; 已抄送 | 黄琪艳 已抄送 01/17 17:16; 已抄送 | 王京海 已抄送 01/17 17:16
A39: 陈 | B39: 2434 | C39: 华中 | D39: 湖北 | E39: 石首新天地店 | F39: 46027 | G39: 46027 | H39: 已提交 | I39: 已收集 | J39: 已通过 | K39: =VLOOKUP(B39,[1]线上建店审批明细!$A:$E,5,0) -> 已抄送 | 线下堂食助理-婷婷 已抄送 01/09 14:25; 已抄送 | 蔡文佳-18916500662-线下运营部 已抄送 01/09 14:25; 已抄送 | 谢芳 已抄送 01/09 14:25; 已抄送 | 线上督导-鹿世鸣-督导部 已抄送 01/09 14:25; 已同意 | 贺龙娇 已同意 01/10 17:33; 已同意 | 杨文慧 已同意 01/10 17:45; 已同意 | 施工监理-范钟欣-13817733545 已同意 01/10 17:51; 已同意 | 王伟清 已同意 01/12 10:19; 已同意 | 刘崇宇-18616022203-督导部 已同意 01/12 17:41; 已同意 | 蔡文佳-18916500662-线下运营部 已同意 01/13 11:37; 已同意 | 线下堂食助理-婷婷 已同意 01/13 11:43; 已同意 | 单玮-13816935059-督导部 已同意 01/13 14:28; 已抄送 | 卢家豪 已抄送 01/13 14:28; 已抄送 | 抖音&快手-周幂-17521714387 已抄送 01/13 14:28; 已同意 | 苏磊 已同意 01/13 14:30; 已抄送 | 翁嘉隆-线上运营总监-13611699917 已抄送 01/13 14:30; 已同意 | 陈宇航-线上助理-18350349892 三平台建店完成 已同意 01/17 17:15; 已抄送 | 谢芳 已抄送 01/17 17:15; 已抄送 | 黄琪艳 已抄送 01/17 17:15; 已抄送 | 王京海 已抄送 01/17 17:15
A40: 窦 | B40: 2432 | C40: 华中 | D40: 河南 | E40: 南阳唐河店 | F40: 46027 | G40: 46027 | H40: 已提交 | I40: 已收集
...
